2021-12-26 21:35:37: CustomError 404: The user with id a91f01b4-e9e9-4016-8c01-c91cb695e58 was not found
CustomError: The user with id a91f01b4-e9e9-4016-8c01-c91cb695e58 was not found
    at C:\Users\diman\Desktop\git\nodejs2021Q4-service\src\resources\users\user.memory.repository.ts:20:25
    at Generator.next (<anonymous>)
    at C:\Users\diman\Desktop\git\nodejs2021Q4-service\src\resources\users\user.memory.repository.ts:8:71
    at new Promise (<anonymous>)
    at __awaiter (C:\Users\diman\Desktop\git\nodejs2021Q4-service\src\resources\users\user.memory.repository.ts:4:12)
    at Object.getOne (C:\Users\diman\Desktop\git\nodejs2021Q4-service\src\resources\users\user.memory.repository.ts:17:65)
    at Object.getOne (C:\Users\diman\Desktop\git\nodejs2021Q4-service\src\resources\users\user.service.ts:6:42)
    at C:\Users\diman\Desktop\git\nodejs2021Q4-service\src\resources\users\user.router.ts:24:39
    at Generator.next (<anonymous>)
    at C:\Users\diman\Desktop\git\nodejs2021Q4-service\src\resources\users\user.router.ts:8:71
2021-12-26 21:37:11: CustomError 404: The user with id a91f01b4-e9e9-4016-8c01-c91cb695e58 was not found
CustomError: The user with id a91f01b4-e9e9-4016-8c01-c91cb695e58 was not found
    at C:\Users\diman\Desktop\git\nodejs2021Q4-service\src\resources\users\user.memory.repository.ts:20:25
    at Generator.next (<anonymous>)
    at C:\Users\diman\Desktop\git\nodejs2021Q4-service\src\resources\users\user.memory.repository.ts:8:71
    at new Promise (<anonymous>)
    at __awaiter (C:\Users\diman\Desktop\git\nodejs2021Q4-service\src\resources\users\user.memory.repository.ts:4:12)
    at Object.getOne (C:\Users\diman\Desktop\git\nodejs2021Q4-service\src\resources\users\user.memory.repository.ts:17:65)
    at Object.getOne (C:\Users\diman\Desktop\git\nodejs2021Q4-service\src\resources\users\user.service.ts:6:42)
    at C:\Users\diman\Desktop\git\nodejs2021Q4-service\src\resources\users\user.router.ts:24:39
    at Generator.next (<anonymous>)
    at C:\Users\diman\Desktop\git\nodejs2021Q4-service\src\resources\users\user.router.ts:8:71
2021-12-26 21:39:29: CustomError 404: The user with id a91f01b4-e9e9-4016-8c01-c91cb695e58 was not found
CustomError: The user with id a91f01b4-e9e9-4016-8c01-c91cb695e58 was not found
    at C:\Users\diman\Desktop\git\nodejs2021Q4-service\src\resources\users\user.memory.repository.ts:20:25
    at Generator.next (<anonymous>)
    at C:\Users\diman\Desktop\git\nodejs2021Q4-service\src\resources\users\user.memory.repository.ts:8:71
    at new Promise (<anonymous>)
    at __awaiter (C:\Users\diman\Desktop\git\nodejs2021Q4-service\src\resources\users\user.memory.repository.ts:4:12)
    at Object.getOne (C:\Users\diman\Desktop\git\nodejs2021Q4-service\src\resources\users\user.memory.repository.ts:17:65)
    at Object.getOne (C:\Users\diman\Desktop\git\nodejs2021Q4-service\src\resources\users\user.service.ts:6:42)
    at C:\Users\diman\Desktop\git\nodejs2021Q4-service\src\resources\users\user.router.ts:24:39
    at Generator.next (<anonymous>)
    at C:\Users\diman\Desktop\git\nodejs2021Q4-service\src\resources\users\user.router.ts:8:71
2021-12-26 21:39:54: CustomError 404: The user with id a91f01b4-e9e9-4016-8c01-c91cb695e58 was not found
CustomError: The user with id a91f01b4-e9e9-4016-8c01-c91cb695e58 was not found
    at C:\Users\diman\Desktop\git\nodejs2021Q4-service\src\resources\users\user.memory.repository.ts:20:25
    at Generator.next (<anonymous>)
    at C:\Users\diman\Desktop\git\nodejs2021Q4-service\src\resources\users\user.memory.repository.ts:8:71
    at new Promise (<anonymous>)
    at __awaiter (C:\Users\diman\Desktop\git\nodejs2021Q4-service\src\resources\users\user.memory.repository.ts:4:12)
    at Object.getOne (C:\Users\diman\Desktop\git\nodejs2021Q4-service\src\resources\users\user.memory.repository.ts:17:65)
    at Object.getOne (C:\Users\diman\Desktop\git\nodejs2021Q4-service\src\resources\users\user.service.ts:6:42)
    at C:\Users\diman\Desktop\git\nodejs2021Q4-service\src\resources\users\user.router.ts:24:39
    at Generator.next (<anonymous>)
    at C:\Users\diman\Desktop\git\nodejs2021Q4-service\src\resources\users\user.router.ts:8:71
2021-12-26 21:39:55: CustomError 404: The user with id a91f01b4-e9e9-4016-8c01-c91cb695e58 was not found
CustomError: The user with id a91f01b4-e9e9-4016-8c01-c91cb695e58 was not found
    at C:\Users\diman\Desktop\git\nodejs2021Q4-service\src\resources\users\user.memory.repository.ts:20:25
    at Generator.next (<anonymous>)
    at C:\Users\diman\Desktop\git\nodejs2021Q4-service\src\resources\users\user.memory.repository.ts:8:71
    at new Promise (<anonymous>)
    at __awaiter (C:\Users\diman\Desktop\git\nodejs2021Q4-service\src\resources\users\user.memory.repository.ts:4:12)
    at Object.getOne (C:\Users\diman\Desktop\git\nodejs2021Q4-service\src\resources\users\user.memory.repository.ts:17:65)
    at Object.getOne (C:\Users\diman\Desktop\git\nodejs2021Q4-service\src\resources\users\user.service.ts:6:42)
    at C:\Users\diman\Desktop\git\nodejs2021Q4-service\src\resources\users\user.router.ts:24:39
    at Generator.next (<anonymous>)
    at C:\Users\diman\Desktop\git\nodejs2021Q4-service\src\resources\users\user.router.ts:8:71
2021-12-26 21:39:56: CustomError 404: The user with id a91f01b4-e9e9-4016-8c01-c91cb695e58 was not found
CustomError: The user with id a91f01b4-e9e9-4016-8c01-c91cb695e58 was not found
    at C:\Users\diman\Desktop\git\nodejs2021Q4-service\src\resources\users\user.memory.repository.ts:20:25
    at Generator.next (<anonymous>)
    at C:\Users\diman\Desktop\git\nodejs2021Q4-service\src\resources\users\user.memory.repository.ts:8:71
    at new Promise (<anonymous>)
    at __awaiter (C:\Users\diman\Desktop\git\nodejs2021Q4-service\src\resources\users\user.memory.repository.ts:4:12)
    at Object.getOne (C:\Users\diman\Desktop\git\nodejs2021Q4-service\src\resources\users\user.memory.repository.ts:17:65)
    at Object.getOne (C:\Users\diman\Desktop\git\nodejs2021Q4-service\src\resources\users\user.service.ts:6:42)
    at C:\Users\diman\Desktop\git\nodejs2021Q4-service\src\resources\users\user.router.ts:24:39
    at Generator.next (<anonymous>)
    at C:\Users\diman\Desktop\git\nodejs2021Q4-service\src\resources\users\user.router.ts:8:71
2021-12-26 21:39:56: CustomError 404: The user with id a91f01b4-e9e9-4016-8c01-c91cb695e58 was not found
CustomError: The user with id a91f01b4-e9e9-4016-8c01-c91cb695e58 was not found
    at C:\Users\diman\Desktop\git\nodejs2021Q4-service\src\resources\users\user.memory.repository.ts:20:25
    at Generator.next (<anonymous>)
    at C:\Users\diman\Desktop\git\nodejs2021Q4-service\src\resources\users\user.memory.repository.ts:8:71
    at new Promise (<anonymous>)
    at __awaiter (C:\Users\diman\Desktop\git\nodejs2021Q4-service\src\resources\users\user.memory.repository.ts:4:12)
    at Object.getOne (C:\Users\diman\Desktop\git\nodejs2021Q4-service\src\resources\users\user.memory.repository.ts:17:65)
    at Object.getOne (C:\Users\diman\Desktop\git\nodejs2021Q4-service\src\resources\users\user.service.ts:6:42)
    at C:\Users\diman\Desktop\git\nodejs2021Q4-service\src\resources\users\user.router.ts:24:39
    at Generator.next (<anonymous>)
    at C:\Users\diman\Desktop\git\nodejs2021Q4-service\src\resources\users\user.router.ts:8:71
2021-12-26 21:40:33: CustomError 404: The user with id a91f01b4-e9e9-4016-8c01-c91cb695e58 was not found
CustomError: The user with id a91f01b4-e9e9-4016-8c01-c91cb695e58 was not found
    at C:\Users\diman\Desktop\git\nodejs2021Q4-service\src\resources\users\user.memory.repository.ts:20:25
    at Generator.next (<anonymous>)
    at C:\Users\diman\Desktop\git\nodejs2021Q4-service\src\resources\users\user.memory.repository.ts:8:71
    at new Promise (<anonymous>)
    at __awaiter (C:\Users\diman\Desktop\git\nodejs2021Q4-service\src\resources\users\user.memory.repository.ts:4:12)
    at Object.getOne (C:\Users\diman\Desktop\git\nodejs2021Q4-service\src\resources\users\user.memory.repository.ts:17:65)
    at Object.getOne (C:\Users\diman\Desktop\git\nodejs2021Q4-service\src\resources\users\user.service.ts:6:42)
    at C:\Users\diman\Desktop\git\nodejs2021Q4-service\src\resources\users\user.router.ts:24:39
    at Generator.next (<anonymous>)
    at C:\Users\diman\Desktop\git\nodejs2021Q4-service\src\resources\users\user.router.ts:8:71
2021-12-26 21:48:13: uncaughtException: Oops!
Error: Oops!
    at Object.<anonymous> (C:\Users\diman\Desktop\git\nodejs2021Q4-service\src\app.ts:36:7)
    at Module._compile (node:internal/modules/cjs/loader:1101:14)
    at Module.m._compile (C:\Users\diman\Desktop\git\nodejs2021Q4-service\node_modules\ts-node\src\index.ts:1371:23)
    at Module._extensions..js (node:internal/modules/cjs/loader:1153:10)
    at Object.require.extensions.<computed> [as .ts] (C:\Users\diman\Desktop\git\nodejs2021Q4-service\node_modules\ts-node\src\index.ts:1374:12)
    at Module.load (node:internal/modules/cjs/loader:981:32)
    at Function.Module._load (node:internal/modules/cjs/loader:822:12)
    at Module.require (node:internal/modules/cjs/loader:1005:19)
    at require (node:internal/modules/cjs/helpers:102:18)
    at Object.<anonymous> (C:\Users\diman\Desktop\git\nodejs2021Q4-service\src\server.ts:2:1)
2021-12-26 22:01:51: Error undefined: test
Error: test
    at C:\Users\diman\Desktop\git\nodejs2021Q4-service\src\resources\users\user.router.ts:12:13
    at Generator.next (<anonymous>)
    at C:\Users\diman\Desktop\git\nodejs2021Q4-service\src\resources\users\user.router.ts:8:71
    at new Promise (<anonymous>)
    at __awaiter (C:\Users\diman\Desktop\git\nodejs2021Q4-service\src\resources\users\user.router.ts:4:12)
    at C:\Users\diman\Desktop\git\nodejs2021Q4-service\src\resources\users\user.router.ts:11:43
    at C:\Users\diman\Desktop\git\nodejs2021Q4-service\src\utils\routerCatch.ts:5:5
    at Layer.handle [as handle_request] (C:\Users\diman\Desktop\git\nodejs2021Q4-service\node_modules\express\lib\router\layer.js:95:5)
    at next (C:\Users\diman\Desktop\git\nodejs2021Q4-service\node_modules\express\lib\router\route.js:137:13)
    at Route.dispatch (C:\Users\diman\Desktop\git\nodejs2021Q4-service\node_modules\express\lib\router\route.js:112:3)
2021-12-26 22:07:49: Error undefined: test
Error: test
    at C:\Users\diman\Desktop\git\nodejs2021Q4-service\src\resources\users\user.router.ts:12:13
    at Generator.next (<anonymous>)
    at C:\Users\diman\Desktop\git\nodejs2021Q4-service\src\resources\users\user.router.ts:8:71
    at new Promise (<anonymous>)
    at __awaiter (C:\Users\diman\Desktop\git\nodejs2021Q4-service\src\resources\users\user.router.ts:4:12)
    at C:\Users\diman\Desktop\git\nodejs2021Q4-service\src\resources\users\user.router.ts:11:43
    at C:\Users\diman\Desktop\git\nodejs2021Q4-service\src\utils\routerCatch.ts:5:5
    at Layer.handle [as handle_request] (C:\Users\diman\Desktop\git\nodejs2021Q4-service\node_modules\express\lib\router\layer.js:95:5)
    at next (C:\Users\diman\Desktop\git\nodejs2021Q4-service\node_modules\express\lib\router\route.js:137:13)
    at Route.dispatch (C:\Users\diman\Desktop\git\nodejs2021Q4-service\node_modules\express\lib\router\route.js:112:3)
